<?xml verison="1.0"?>
<robot name ="fourleg">

<link name = "base_link">
    <visual>
        <origin rpy = "0 0 0" xyz = "0 0 0" />
        <geometry>
            <mesh filename = "./fourleg/chassis.obj" scale = "0.01 0.01 0.01" />
        </geometry>
    </visual>
    <collision>
        <origin rpy = "0 0 0" xyz = "0 0 0" />
        <geometry>
            <box size="1.45 1 0.4 "/>
        </geometry>
    </collision>
    <inertial>
        <mass value="1"/>
        <inertia ixx="1.0" ixy="0.0" ixz="0.0" iyy="1.0" iyz="0.0" izz="1.0"/>
    </inertial>
</link>

<link name = "link4">
    <visual>
        <origin rpy = "0 0 0" xyz = "0 0 -0.1" />
        <geometry>
            <mesh filename = "./fourleg/leg.obj" scale = "0.01 0.01 0.01" />
        </geometry>
    </visual>
    <collision>
        <origin rpy = "0 0 0" xyz = "0 0 -0.1" />
        <geometry>
            <box size=" 0.1 0.1 0.35"/>
        </geometry>
    </collision>
    <inertial>
        <mass value="1"/>
        <inertia ixx="1.0" ixy="0.0" ixz="0.0" iyy="1.0" iyz="0.0" izz="1.0"/>
    </inertial>
</link>

<joint name = "base_link_link4" type = "continuous">
    <parent link = "base_link"/>
    <child link = "link4"/>
    <origin xyz = "0.35 -0.75 0" rpy = "0 0 0" />
    <axis xyz = "0 1 0" />
</joint>

<link name = "link3">
    <visual>
        <origin rpy = "0 0 0" xyz = "0 0 -0.1" />
        <geometry>
            <mesh filename = "./fourleg/leg.obj" scale = "0.01 0.01 0.01" />
        </geometry>
    </visual>
    <collision>
        <origin rpy = "0 0 0" xyz = "0 0 -0.1" />
        <geometry>
            <box size="0.1 0.1 0.35"/>
        </geometry>
    </collision>
    <inertial>
        <mass value="1"/>
        <inertia ixx="1.0" ixy="0.0" ixz="0.0" iyy="1.0" iyz="0.0" izz="1.0"/>
    </inertial>
</link>

<joint name = "base_link_link3" type = "continuous">
    <parent link = "base_link"/>
    <child link = "link3"/>
    <origin xyz = "-0.35 -0.75 0" rpy = "0 0 0" />
    <axis xyz = "0 1 0" />
</joint>

<link name = "link2">
    <visual>
        <origin rpy = "0 0 0" xyz = "0 0 -0.1" />
        <geometry>
            <mesh filename = "./fourleg/leg.obj" scale = "0.01 0.01 0.01" />
        </geometry>
    </visual>
    <collision>
        <origin rpy = "0 0 0" xyz = "0 0 -0.1" />
        <geometry>
            <box size="0.1 0.1 0.35"/>
        </geometry>
    </collision>
    <inertial>
        <mass value="1"/>
        <inertia ixx="1.0" ixy="0.0" ixz="0.0" iyy="1.0" iyz="0.0" izz="1.0"/>
    </inertial>
</link>

<joint name = "base_link_link2" type = "continuous">
    <parent link = "base_link"/>
    <child link = "link2"/>
    <origin xyz = "-0.35 0.75 0" rpy = "0 0 0" />
    <axis xyz = "0 1 0" />
</joint>

<link name = "link1">
    <visual>
        <origin rpy = "0 0 0" xyz = "0 0 -0.1" />
        <geometry>
            <mesh filename = "./fourleg/leg.obj" scale = "0.01 0.01 0.01" />
        </geometry>
    </visual>
    <collision>
        <origin rpy = "0 0 0" xyz = "0 0 -0.1" />
        <geometry>
            <box size="0.1 0.1 0.35"/>
        </geometry>
    </collision>
    <inertial>
        <mass value="1"/>
        <inertia ixx="1.0" ixy="0.0" ixz="0.0" iyy="1.0" iyz="0.0" izz="1.0"/>
    </inertial>
</link>

<joint name = "base_link_link1" type = "continuous">
    <parent link = "base_link"/>
    <child link = "link1"/>
    <origin xyz = "0.35 0.75 0" rpy = "0 0 0" />
    <axis xyz = "0 1 0" />
</joint>

</robot>
