<?xml verison="1.0"?>
<robot name ="triplebeam_manipulator">

<link name = "fixed_base_link">
 <visual>
  <origin rpy = "0 0 1.75" xyz = "0 0 0" />
  <geometry>
    <mesh filename = "./triplebeam/beam.obj" scale = "0.1 0.1 0.1" />
  </geometry>
 </visual>
</link>

<link name = "link1">
 <visual>
  <origin rpy = "0 0 0" xyz = "0 0 1.6" />
  <geometry>
    <mesh filename = "./triplebeam/beam.obj" scale = "0.1 0.1 0.1" />
  </geometry>
 </visual>
</link>

<link name = "link2">
 <visual>
  <origin rpy = "0 0 0" xyz = "0 0 1.6" />
  <geometry>
    <mesh filename = "./triplebeam/beam.obj" scale = "0.1 0.1 0.1" />
  </geometry>
 </visual>
</link>

<joint name = "base_link_link1" type = "continuous">
  <parent link = "fixed_base_link"/>
  <child link = "link1"/>
   <origin xyz = "0 1.2 1.6" rpy = "0 0 0" />
   <axis xyz = "0 1 0" />
</joint>

<joint name = "link1_link2" type = "continuous">
  <parent link = "link1"/>
  <child link = "link2"/>
   <origin xyz = "0 -1.2 3.3" rpy = "0 0 0" />
   <axis xyz = "0 1 0" />
</joint>


</robot>
