<?xml verison="1.0"?>
<robot name ="fourleg2">

<link name = "base_link">
    <visual>
        <origin rpy = "0 0 0" xyz = "0 0 0" />
        <geometry>
            <box size="4.35 3 1.2"/>
        </geometry>
    </visual>
    <collision>
        <origin rpy = "0 0 0" xyz = "0 0 0" />
        <geometry>
            <box size="4.35 3 1.2"/>
        </geometry>
    </collision>
    <inertial>
        <mass value="20"/>
        <inertia ixx="1.0" ixy="0.0" ixz="0.0" iyy="1.0" iyz="0.0" izz="1.0"/>
    </inertial>
</link>

<link name = "link4">
    <visual>
        <origin rpy = "0 0 0" xyz = "0 0 -0.4" />
        <geometry>
            <box size=" 0.3 0.3 1.05"/>
        </geometry>
    </visual>
    <collision>
        <origin rpy = "0 0 0" xyz = "0 0 -0.4" />
        <geometry>
            <box size=" 0.3 0.3 1.05"/>
        </geometry>
    </collision>
    <inertial>
        <mass value="1"/>
        <inertia ixx="1.0" ixy="0.0" ixz="0.0" iyy="1.0" iyz="0.0" izz="1.0"/>
    </inertial>
</link>

<joint name = "base_link_link4" type = "continuous">
    <parent link = "base_link"/>
    <child link = "link4"/>
    <origin xyz = "1.2 -1.8 0" rpy = "0 0 0" />
    <axis xyz = "0 1 0" />
</joint>

<link name = "link3">
    <visual>
        <origin rpy = "0 0 0" xyz = "0 0 -0.4" />
        <geometry>
            <box size=" 0.3 0.3 1.05"/>
        </geometry>
    </visual>
    <collision>
        <origin rpy = "0 0 0" xyz = "0 0 -0.4" />
        <geometry>
            <box size="0.3 0.3 1.05"/>
        </geometry>
    </collision>
    <inertial>
        <mass value="1"/>
        <inertia ixx="1.0" ixy="0.0" ixz="0.0" iyy="1.0" iyz="0.0" izz="1.0"/>
    </inertial>
</link>

<joint name = "base_link_link3" type = "continuous">
    <parent link = "base_link"/>
    <child link = "link3"/>
    <origin xyz = "-1.2 -1.8 0" rpy = "0 0 0" />
    <axis xyz = "0 1 0" />
</joint>

<link name = "link2">
    <visual>
        <origin rpy = "0 0 0" xyz = "0 0 -0.4" />
        <geometry>
            <box size=" 0.3 0.3 1.05"/>
        </geometry>
    </visual>
    <collision>
        <origin rpy = "0 0 0" xyz = "0 0 -0.4" />
        <geometry>
            <box size="0.3 0.3 1.05"/>
        </geometry>
    </collision>
    <inertial>
        <mass value="1"/>
        <inertia ixx="1.0" ixy="0.0" ixz="0.0" iyy="1.0" iyz="0.0" izz="1.0"/>
    </inertial>
</link>

<joint name = "base_link_link2" type = "continuous">
    <parent link = "base_link"/>
    <child link = "link2"/>
    <origin xyz = "-1.2 1.8 0" rpy = "0 0 0" />
    <axis xyz = "0 1 0" />
</joint>

<link name = "link1">
    <visual>
        <origin rpy = "0 0 0" xyz = "0 0 -0.4" />
        <geometry>
            <box size=" 0.3 0.3 1.05"/>
        </geometry>
    </visual>
    <collision>
        <origin rpy = "0 0 0" xyz = "0 0 -0.4" />
        <geometry>
            <box size="0.3 0.3 1.05"/>
        </geometry>
    </collision>
    <inertial>
        <mass value="1"/>
        <inertia ixx="1.0" ixy="0.0" ixz="0.0" iyy="1.0" iyz="0.0" izz="1.0"/>
    </inertial>
</link>

<joint name = "base_link_link1" type = "continuous">
    <parent link = "base_link"/>
    <child link = "link1"/>
    <origin xyz = "1.2 1.8 0" rpy = "0 0 0" />
    <axis xyz = "0 1 0" />
</joint>

<link name = "link4_2">
    <visual>
        <origin rpy = "0 0 0" xyz = "0 0 -0.5" />
        <geometry>
            <box size=" 0.3 0.3 1.05"/>
        </geometry>
    </visual>
    <visual>
        <origin rpy = "0 0 0" xyz = "0 0 -1" />
        <geometry>
            <sphere radius = "0.2"/>
        </geometry>
    </visual>
    <collision>
        <origin rpy = "0 0 0" xyz = "0 0 -0.5" />
        <geometry>
            <box size=" 0.3 0.3 1.05"/>
        </geometry>
    </collision>
    <collision>
        <origin rpy = "0 0 0" xyz = "0 0 -1" />
        <geometry>
            <sphere radius = "0.2"/>
        </geometry>
    </collision>
    <inertial>
        <mass value="1"/>
        <inertia ixx="1.0" ixy="0.0" ixz="0.0" iyy="1.0" iyz="0.0" izz="1.0"/>
    </inertial>
</link>

<link name = "link3_2">
    <visual>
        <origin rpy = "0 0 0" xyz = "0 0 -0.5" />
        <geometry>
            <box size=" 0.3 0.3 1.05"/>
        </geometry>
    </visual>
    <visual>
        <origin rpy = "0 0 0" xyz = "0 0 -1" />
        <geometry>
            <sphere radius = "0.2"/>
        </geometry>
    </visual>
    <collision>
        <origin rpy = "0 0 0" xyz = "0 0 -0.5" />
        <geometry>
            <box size=" 0.3 0.3 1.05"/>
        </geometry>
    </collision>
    <collision>
        <origin rpy = "0 0 0" xyz = "0 0 -1" />
        <geometry>
            <sphere radius = "0.2"/>
        </geometry>
    </collision>
    <inertial>
        <mass value="1"/>
        <inertia ixx="1.0" ixy="0.0" ixz="0.0" iyy="1.0" iyz="0.0" izz="1.0"/>
    </inertial>
</link>

<link name = "link2_2">
    <visual>
        <origin rpy = "0 0 0" xyz = "0 0 -0.5" />
        <geometry>
            <box size=" 0.3 0.3 1.05"/>
        </geometry>
    </visual>
    <visual>
        <origin rpy = "0 0 0" xyz = "0 0 -1" />
        <geometry>
            <sphere radius = "0.2"/>
        </geometry>
    </visual>
    <collision>
        <origin rpy = "0 0 0" xyz = "0 0 -0.5" />
        <geometry>
            <box size=" 0.3 0.3 1.05"/>
        </geometry>
    </collision>
    <collision>
        <origin rpy = "0 0 0" xyz = "0 0 -1" />
        <geometry>
            <sphere radius = "0.2"/>
        </geometry>
    </collision>
    <inertial>
        <mass value="1"/>
        <inertia ixx="1.0" ixy="0.0" ixz="0.0" iyy="1.0" iyz="0.0" izz="1.0"/>
    </inertial>
</link>

<link name = "link1_2">
    <visual>
        <origin rpy = "0 0 0" xyz = "0 0 -0.5" />
        <geometry>
            <box size=" 0.3 0.3 1.05"/>
        </geometry>
    </visual>
    <visual>
        <origin rpy = "0 0 0" xyz = "0 0 -1" />
        <geometry>
            <sphere radius = "0.2"/>
        </geometry>
    </visual>
    <collision>
        <origin rpy = "0 0 0" xyz = "0 0 -0.5" />
        <geometry>
            <box size=" 0.3 0.3 1.05"/>
        </geometry>
    </collision>
    <collision>
        <origin rpy = "0 0 0" xyz = "0 0 -1" />
        <geometry>
            <sphere radius = "0.2"/>
        </geometry>
    </collision>
    <inertial>
        <mass value="1"/>
        <inertia ixx="1.0" ixy="0.0" ixz="0.0" iyy="1.0" iyz="0.0" izz="1.0"/>
    </inertial>
</link>

<joint name = "link4_link4_2" type = "continuous">
    <parent link = "link4"/>
    <child link = "link4_2"/>
    <origin xyz = "0 0 -1" rpy = "0 0 0" />
    <axis xyz = "0 1 0" />
</joint>

<joint name = "link3_link3_2" type = "continuous">
    <parent link = "link3"/>
    <child link = "link3_2"/>
    <origin xyz = "0 0 -1" rpy = "0 0 0" />
    <axis xyz = "0 1 0" />
</joint>

<joint name = "link2_link2_2" type = "continuous">
    <parent link = "link2"/>
    <child link = "link2_2"/>
    <origin xyz = "0 0 -1" rpy = "0 0 0" />
    <axis xyz = "0 1 0" />
</joint>

<joint name = "link1_link1_2" type = "continuous">
    <parent link = "link1"/>
    <child link = "link1_2"/>
    <origin xyz = "0 0 -1" rpy = "0 0 0" />
    <axis xyz = "0 1 0" />
</joint>

</robot>
