<?xml verison="1.0"?>
<robot name ="fourleg3">
<link name = "chassis">
    <visual>
        <origin rpy = "0 0 0" xyz = "0 0 0" />
        <geometry>
            <box size="0.16 0.06 0.05"/>
        </geometry>
    </visual>
    <inertial>
        <mass value="0.2"/>
        <inertia ixx="1.0" ixy="0.0" ixz="0.0" iyy="1.0" iyz="0.0" izz="1.0"/>
    </inertial>
</link>

<joint name = "chassis-fl_cyl" type = "continuous">
    <parent link = "chassis"/>
    <child link = "fl_cyl"/>
    <origin xyz = "0.065 0.02 0" rpy = "0 0 0" />
    <axis xyz = "0 0 1" />
</joint>

<link name = "fl_cyl">
    <visual>
        <origin rpy = "0 0 0" xyz = "0 0.0175 0" />
        <geometry>
            <box size="0.028 0.035 0.002"/>
        </geometry>
    </visual>
    <inertial>
        <mass value="0.001"/>
        <inertia ixx="1.0" ixy="0.0" ixz="0.0" iyy="1.0" iyz="0.0" izz="1.0"/>
    </inertial>
</link>

<joint name = "fl_cyl-fl_upper" type = "continuous">
    <parent link = "fl_cyl"/>
    <child link = "fl_upper"/>
    <origin xyz = "0 0.035 0" rpy = "0 0 0" />
    <axis xyz = "0 1 0" />
</joint>

<link name = "fl_upper">
    <visual>
        <origin rpy = "0 0 0" xyz = "0 0 -0.03" />
        <geometry>
            <box size="0.018 0.018 0.06"/>
        </geometry>
    </visual>
    <inertial>
        <mass value="0.001"/>
        <inertia ixx="1.0" ixy="0.0" ixz="0.0" iyy="1.0" iyz="0.0" izz="1.0"/>
    </inertial>
</link>

<joint name = "fl_upper-fl_lower" type = "continuous">
    <parent link = "fl_upper"/>
    <child link = "fl_lower"/>
    <origin xyz = "0 0 -0.06" rpy = "0 0 0" />
    <axis xyz = "0 1 0" />
</joint>

<link name = "fl_lower">
    <visual>
        <origin rpy = "0 0 0" xyz = "0 0 -0.03" />
        <geometry>
            <box size="0.018 0.018 0.06"/>
        </geometry>
    </visual>
    <collision>
        <origin rpy = "0 0 0" xyz = "0 0 -0.06" />
        <geometry>
            <sphere radius = "0.009"/>
        </geometry>
    </collision>
    <inertial>
        <mass value="0.001"/>
        <inertia ixx="1.0" ixy="0.0" ixz="0.0" iyy="1.0" iyz="0.0" izz="1.0"/>
    </inertial>
</link>

<joint name = "chassis-fr_cyl" type = "continuous">
    <parent link = "chassis"/>
    <child link = "fr_cyl"/>
    <origin xyz = "0.065 -0.02 0" rpy = "0 0 0" />
    <axis xyz = "0 0 1" />
</joint>

<link name = "fr_cyl">
    <visual>
        <origin rpy = "0 0 0" xyz = "0 -0.0175 0" />
        <geometry>
            <box size="0.028 0.035 0.002"/>
        </geometry>
    </visual>
    <inertial>
        <mass value="0.001"/>
        <inertia ixx="1.0" ixy="0.0" ixz="0.0" iyy="1.0" iyz="0.0" izz="1.0"/>
    </inertial>
</link>

<joint name = "fr_cyl-fr_upper" type = "continuous">
    <parent link = "fr_cyl"/>
    <child link = "fr_upper"/>
    <origin xyz = "0 -0.035 0" rpy = "0 0 0" />
    <axis xyz = "0 1 0" />
</joint>

<link name = "fr_upper">
    <visual>
        <origin rpy = "0 0 0" xyz = "0 0 -0.03" />
        <geometry>
            <box size="0.018 0.018 0.06"/>
        </geometry>
    </visual>
    <inertial>
        <mass value="0.001"/>
        <inertia ixx="1.0" ixy="0.0" ixz="0.0" iyy="1.0" iyz="0.0" izz="1.0"/>
    </inertial>
</link>

<joint name = "fr_upper-fr_lower" type = "continuous">
    <parent link = "fr_upper"/>
    <child link = "fr_lower"/>
    <origin xyz = "0 0 -0.06" rpy = "0 0 0" />
    <axis xyz = "0 1 0" />
</joint>

<link name = "fr_lower">
    <visual>
        <origin rpy = "0 0 0" xyz = "0 0 -0.03" />
        <geometry>
            <box size="0.018 0.018 0.06"/>
        </geometry>
    </visual>
    <collision>
        <origin rpy = "0 0 0" xyz = "0 0 -0.06" />
        <geometry>
            <sphere radius = "0.009"/>
        </geometry>
    </collision>
    <inertial>
        <mass value="0.001"/>
        <inertia ixx="1.0" ixy="0.0" ixz="0.0" iyy="1.0" iyz="0.0" izz="1.0"/>
    </inertial>
</link>

<joint name = "chassis-bl_cyl" type = "continuous">
    <parent link = "chassis"/>
    <child link = "bl_cyl"/>
    <origin xyz = "-0.065 0.02 0" rpy = "0 0 0" />
    <axis xyz = "0 0 1" />
</joint>

<link name = "bl_cyl">
    <visual>
        <origin rpy = "0 0 0" xyz = "0 0.0175 0" />
        <geometry>
            <box size="0.028 0.035 0.002"/>
        </geometry>
    </visual>
    <inertial>
        <mass value="0.001"/>
        <inertia ixx="1.0" ixy="0.0" ixz="0.0" iyy="1.0" iyz="0.0" izz="1.0"/>
    </inertial>
</link>

<joint name = "bl_cyl-bl_upper" type = "continuous">
    <parent link = "bl_cyl"/>
    <child link = "bl_upper"/>
    <origin xyz = "0 0.035 0" rpy = "0 0 0" />
    <axis xyz = "0 1 0" />
</joint>

<link name = "bl_upper">
    <visual>
        <origin rpy = "0 0 0" xyz = "0 0 -0.03" />
        <geometry>
            <box size="0.018 0.018 0.06"/>
        </geometry>
    </visual>
    <inertial>
        <mass value="0.001"/>
        <inertia ixx="1.0" ixy="0.0" ixz="0.0" iyy="1.0" iyz="0.0" izz="1.0"/>
    </inertial>
</link>

<joint name = "bl_upper-bl_lower" type = "continuous">
    <parent link = "bl_upper"/>
    <child link = "bl_lower"/>
    <origin xyz = "0 0 -0.06" rpy = "0 0 0" />
    <axis xyz = "0 1 0" />
</joint>

<link name = "bl_lower">
    <visual>
        <origin rpy = "0 0 0" xyz = "0 0 -0.03" />
        <geometry>
            <box size="0.018 0.018 0.06"/>
        </geometry>
    </visual>
    <collision>
        <origin rpy = "0 0 0" xyz = "0 0 -0.06" />
        <geometry>
            <sphere radius = "0.009"/>
        </geometry>
    </collision>
    <inertial>
        <mass value="0.001"/>
        <inertia ixx="1.0" ixy="0.0" ixz="0.0" iyy="1.0" iyz="0.0" izz="1.0"/>
    </inertial>
</link>

<joint name = "chassis-br_cyl" type = "continuous">
    <parent link = "chassis"/>
    <child link = "br_cyl"/>
    <origin xyz = "-0.065 -0.02 0" rpy = "0 0 0" />
    <axis xyz = "0 0 1" />
</joint>

<link name = "br_cyl">
    <visual>
        <origin rpy = "0 0 0" xyz = "0 -0.0175 0" />
        <geometry>
            <box size="0.028 0.035 0.002"/>
        </geometry>
    </visual>
    <inertial>
        <mass value="0.001"/>
        <inertia ixx="1.0" ixy="0.0" ixz="0.0" iyy="1.0" iyz="0.0" izz="1.0"/>
    </inertial>
</link>

<joint name = "br_cyl-br_upper" type = "continuous">
    <parent link = "br_cyl"/>
    <child link = "br_upper"/>
    <origin xyz = "0 -0.035 0" rpy = "0 0 0" />
    <axis xyz = "0 1 0" />
</joint>

<link name = "br_upper">
    <visual>
        <origin rpy = "0 0 0" xyz = "0 0 -0.03" />
        <geometry>
            <box size="0.018 0.018 0.06"/>
        </geometry>
    </visual>
    <inertial>
        <mass value="0.001"/>
        <inertia ixx="1.0" ixy="0.0" ixz="0.0" iyy="1.0" iyz="0.0" izz="1.0"/>
    </inertial>
</link>

<joint name = "br_upper-br_lower" type = "continuous">
    <parent link = "br_upper"/>
    <child link = "br_lower"/>
    <origin xyz = "0 0 -0.06" rpy = "0 0 0" />
    <axis xyz = "0 1 0" />
</joint>

<link name = "br_lower">
    <visual>
        <origin rpy = "0 0 0" xyz = "0 0 -0.03" />
        <geometry>
            <box size="0.018 0.018 0.06"/>
        </geometry>
    </visual>
    <collision>
        <origin rpy = "0 0 0" xyz = "0 0 -0.06" />
        <geometry>
            <sphere radius = "0.009"/>
        </geometry>
    </collision>
    <inertial>
        <mass value="0.001"/>
        <inertia ixx="1.0" ixy="0.0" ixz="0.0" iyy="1.0" iyz="0.0" izz="1.0"/>
    </inertial>
</link>
</robot>
