<?xml version="1.0"?>
<robot name ="three_wheels">

<material name="blue">
    <color rgba="0 0 0.8 1"/>
</material>
<material name="black">
    <color rgba="0 0 0 1"/>
</material>
<material name="white">
    <color rgba="1 1 1 1"/>
</material>
<material name="red">
    <color rgba="0.8 0 0 1"/>
</material>

<link name = "chassis">
    <visual>
        <geometry>
            <box size="3 1 0.5"/>
        </geometry>
        <material name="red"/>
    </visual>
    <collision>
        <geometry>
            <box size="3 1 0.5"/>
        </geometry>
    </collision>
    <inertial>
        <mass value="1"/>
        <inertia ixx="1.0" ixy="0.0" ixz="0.0" iyy="1.0" iyz="0.0" izz="1.0"/>
    </inertial>
</link>

<link name = "wheel_front">
    <visual>
        <geometry>
            <sphere radius = "0.2"/>
        </geometry>
        <material name="red"/>
    </visual>
    <collision>
        <geometry>
            <cylinder length = "0.3" radius = "0.2"/>
        </geometry>
    </collision>
    <inertial>
        <mass value="1"/>
        <inertia ixx="1.0" ixy="0.0" ixz="0.0" iyy="1.0" iyz="0.0" izz="1.0"/>
    </inertial>
</link>

<link name = "wheel_rl">
    <visual>
        <geometry>
            <cylinder length = "0.3" radius = "0.65"/>
        </geometry>
        <material name="red"/>
    </visual>
    <collision>
        <geometry>
            <cylinder length = "0.3" radius = "0.65"/>
        </geometry>
    </collision>
    <inertial>
        <mass value="1"/>
        <inertia ixx="1.0" ixy="0.0" ixz="0.0" iyy="1.0" iyz="0.0" izz="1.0"/>
    </inertial>
</link>

<link name = "wheel_rr">
    <visual>
        <geometry>
            <cylinder length = "0.3" radius = "0.65"/>
        </geometry>
        <material name="red"/>
    </visual>
    <collision>
        <geometry>
            <cylinder length = "0.3" radius = "0.65"/>
        </geometry>
    </collision>
    <inertial>
        <mass value="1"/>
        <inertia ixx="1.0" ixy="0.0" ixz="0.0" iyy="1.0" iyz="0.0" izz="1.0"/>
    </inertial>
</link>

<joint name = "chassis_wheel_front" type = "fixed">
    <parent link = "chassis"/>
    <child link = "wheel_front"/>
    <origin xyz = "1.2 0 -0.45" rpy = "1.57 0 0" />
    <axis xyz = "0 0 1" />
</joint>

<joint name = "chassis_wheel_rl" type = "continuous">
    <parent link = "chassis"/>
    <child link = "wheel_rl"/>
    <origin xyz = "-1 -1.5 0" rpy = "1.57 0 0" />
    <axis xyz = "0 0 1" />
</joint>

<joint name = "chassis_wheel_rr" type = "continuous">
    <parent link = "chassis"/>
    <child link = "wheel_rr"/>
    <origin xyz = "-1 1.5 0" rpy = "1.57 0 0" />
    <axis xyz = "0 0 1" />
</joint>

<motor name = "motor_rr">
    <joint name = "chassis_wheel_rr"/>
    <!-- location is with respect to the joint's parent frame -->
    <mass value = "1" xyz = "-1 0.5 0"/>
</motor>

<motor name = "motor_rl">
    <joint name = "chassis_wheel_rl"/>
    <!-- location is with respect to the joint's parent frame -->
    <mass value = "1" xyz = "-1 -0.5 0"/>
</motor>

<extra_mass name = "main_board">
    <link name = "chassis"/>
    <!-- location is in the link's ref frame -->
    <mass value = "1" xyz = "0 0 0"/>
</extra_mass>
</robot>
